<mujoco model="go2_with_diy_leg">
  <compiler angle="radian" meshdir="/home/taie/Desktop/mujoco_playground/leg_manipulator/mjcf/meshes/" autolimits="true"/>

  <option timestep="0.004" iterations="4" solver="Newton"/>

  <default>
    <geom friction="1.0 0.005 0.0001" condim="3" contype="1" conaffinity="1"/>
    <joint damping="0.5" armature="0.01"/>
  </default>

  <asset>
    <texture name="grid" type="2d" builtin="checker" rgb1="0.9 0.9 0.9" rgb2="0.6 0.6 0.6" width="512" height="512" mark="edge" markrgb="0.2 0.2 0.2"/>
    <material name="grid_mat" texture="grid" texrepeat="5 5" texuniform="true" reflectance="0.1"/>
    <mesh name="base" content_type="model/obj" file="base.obj"/>
    <mesh name="hip" content_type="model/obj" file="hip.obj"/>
    <mesh name="thigh" content_type="model/obj" file="thigh.obj"/>
    <mesh name="base_link" content_type="model/stl" file="base_link.STL"/>
    <mesh name="link1" content_type="model/stl" file="link1.STL"/>
    <mesh name="link2" content_type="model/stl" file="link2.STL"/>
    <mesh name="link3" content_type="model/stl" file="link3.STL"/>
    <mesh name="link4" content_type="model/stl" file="link4.STL"/>
    <mesh name="thigh_mirror" content_type="model/obj" file="thigh_mirror.obj"/>
    <mesh name="calf" content_type="model/obj" file="calf.obj"/>
    <mesh name="foot" content_type="model/obj" file="foot.obj"/>
    <mesh name="calf_mirror" content_type="model/obj" file="calf_mirror.obj"/>
  </asset>

    <worldbody>
    <light pos="0 0 3" dir="0 0 -1" diffuse="0.8 0.8 0.8"/>
    <geom name="ground" type="plane" size="50 50 0.1" material="grid_mat" condim="3" contype="1" conaffinity="1"/>
    <body name="base" pos="0 0 0.35">
      <freejoint name="root"/>
      <inertial pos="0.021112 0 -0.005366" mass="6.921" diaginertia="0.107 0.098077 0.02448"/>
      <site name="imu" pos="-0.02557 0 0.04232" size="0.01"/>
  <geom type="mesh" contype="0" conaffinity="0" group="1" density="0" rgba="0.671705 0.692426 0.77427 1" mesh="base"/>
      <geom size="0.1881 0.04675 0.057" type="box" rgba="0.671705 0.692426 0.77427 1"/>
      <geom size="0.05 0.045" pos="0.285 0 0.01" type="cylinder"/>
      <geom size="0.047" pos="0.293 0 -0.06"/>
        <body name="FL_hip" pos="0.1934 0.0465 0">
          <inertial pos="-0.004756 0.00171489 -9.28162e-05" quat="0.497627 0.500003 0.504441 0.497899" mass="0.767" diaginertia="0.000998282 0.00065837 0.000539924"/>
          <joint name="FL_hip_joint" pos="0 0 0" axis="1 0 0" range="-1.0472 1.0472" actuatorfrcrange="-23.7 23.7"/>
          <geom type="mesh" contype="0" conaffinity="0" group="1" density="0" rgba="0.671705 0.692426 0.77427 1" mesh="hip"/>
          <geom size="0.046 0.02" pos="0 0.08 0" quat="0.707107 0.707107 0 0" type="cylinder" rgba="0.671705 0.692426 0.77427 1"/>
          <body name="FL_thigh" pos="0 0.0955 0">
            <inertial pos="-0.00374 -0.0223 -0.0327" quat="0.829533 0.0847635 -0.0200632 0.551623" mass="1.152" diaginertia="0.00594973 0.00584149 0.000878787"/>
            <joint name="FL_thigh_joint" pos="0 0 0" axis="0 1 0" range="-1.5708 3.4907" actuatorfrcrange="-23.7 23.7"/>
            <geom type="mesh" contype="0" conaffinity="0" group="1" density="0" rgba="0.671705 0.692426 0.77427 1" mesh="thigh"/>
            <geom size="0.1065 0.01225 0.017" pos="0 0 -0.1065" quat="0.707107 0 0.707107 0" type="box" rgba="0.671705 0.692426 0.77427 1"/>
            <body name="FL_diy_base_link" pos="0 -0.002 -0.212" quat="0.707105 0 -0.707108 0">
              <inertial pos="-0.102102 -1.23372e-05 0.0495365" quat="0.465159 0.532549 0.531746 0.466118" mass="0.228917" diaginertia="0.000613223 0.000612296 6.36283e-05"/>
              <joint name="FL_calf_joint" pos="0 0 0" axis="0 1 0" range="-2.9 -1.2" actuatorfrcrange="-45.43 45.43"/>
              <geom type="mesh" contype="0" conaffinity="0" group="1" density="0" rgba="0.627451 0.627451 0.627451 1" mesh="base_link"/>
              <geom type="mesh" rgba="0.627451 0.627451 0.627451 1" mesh="base_link"/>
              <body name="FL_diy_link1" pos="-0.022741 -5e-05 0.032" quat="-3.67321e-06 1 0 0">
                <inertial pos="-0.128815 6.16693e-05 0.0174845" quat="0.60809 0.393539 0.405553 0.557567" mass="0.0589547" diaginertia="1.49592e-05 1.38269e-05 1.14707e-05"/>
                <joint name="FL_diy_joint1" pos="0 0 0" axis="1 0 0" type="slide" range="0 0.1" actuatorfrcrange="-40 40"/>
                <geom type="mesh" contype="0" conaffinity="0" group="1" density="0" rgba="0.627451 0.627451 0.627451 1" mesh="link1"/>
                <geom type="mesh" rgba="0.627451 0.627451 0.627451 1" mesh="link1"/>
                <body name="FL_diy_link2" pos="-0.145983 -0.0292 0.0227">
                  <inertial pos="-0.0412401 0.029 -0.00237298" quat="0.492327 0.492327 -0.507557 0.507557" mass="0.0492722" diaginertia="2.51508e-05 1.61636e-05 1.49982e-05"/>
                  <joint name="FL_diy_joint2" pos="0 0 0" axis="0 -1 0" range="-2.4 0.67" actuatorfrcrange="-4.9 4.9"/>
                  <geom type="mesh" contype="0" conaffinity="0" group="1" density="0" rgba="0.627451 0.627451 0.627451 1" mesh="link2"/>
                  <geom type="mesh" rgba="0.627451 0.627451 0.627451 1" mesh="link2"/>
                  <body name="FL_diy_link3" pos="-0.050675 0.029 0.017145">
                    <inertial pos="-0.0875706 0.00129801 0.0260546" quat="0.38206 0.600628 0.593439 0.375642" mass="0.111403" diaginertia="0.000168687 0.000164287 1.93189e-05"/>
                    <joint name="FL_diy_joint3" pos="0 0 0" axis="0.46021 0 0.88781" range="-1.42 1.45" actuatorfrcrange="-1.39 1.39"/>
                    <geom type="mesh" contype="0" conaffinity="0" group="1" density="0" rgba="0.627451 0.627451 0.627451 1" mesh="link3"/>
                    <geom type="mesh" rgba="0.627451 0.627451 0.627451 1" mesh="link3"/>
                    <body name="FL_diy_link4" pos="-0.12194 -0.015927 0.044362">
                      <inertial pos="-0.0320231 0.0188395 0.019613" quat="0.420708 0.574598 0.569492 0.410513" mass="0.0268788" diaginertia="1.15938e-05 1.13104e-05 1.68093e-06"/>
                      <joint name="FL_diy_joint4" pos="0 0 0" axis="0.014315 0.99987 -0.0074203" range="-0.17 1.4" actuatorfrcrange="-1.39 1.39"/>
                      <geom type="mesh" contype="0" conaffinity="0" group="1" density="0" rgba="0.627451 0.627451 0.627451 1" mesh="link4"/>
                      <geom type="mesh" rgba="0.627451 0.627451 0.627451 1" mesh="link4"/>
                    </body>
                  </body>
                </body>
              </body>
            </body>
          </body>
        </body>
        <body name="FR_hip" pos="0.1934 -0.0465 0">
          <inertial pos="-0.00479081 -0.00171489 -9.28162e-05" quat="0.497915 0.504477 0.499987 0.497592" mass="0.767" diaginertia="0.000998028 0.000658115 0.000539924"/>
          <joint name="FR_hip_joint" pos="0 0 0" axis="1 0 0" range="-1.0472 1.0472" actuatorfrcrange="-23.7 23.7"/>
          <geom quat="4.63268e-05 1 0 0" type="mesh" contype="0" conaffinity="0" group="1" density="0" rgba="0.671705 0.692426 0.77427 1" mesh="hip"/>
          <geom size="0.046 0.02" pos="0 -0.08 0" quat="0.707107 0.707107 0 0" type="cylinder" rgba="0.671705 0.692426 0.77427 1"/>
          <body name="FR_thigh" pos="0 -0.0955 0">
            <inertial pos="-0.00374 0.0223 -0.0327" quat="0.551623 -0.0200632 0.0847635 0.829533" mass="1.152" diaginertia="0.00594973 0.00584149 0.000878787"/>
            <joint name="FR_thigh_joint" pos="0 0 0" axis="0 1 0" range="-1.5708 3.4907" actuatorfrcrange="-23.7 23.7"/>
            <geom type="mesh" contype="0" conaffinity="0" group="1" density="0" rgba="0.671705 0.692426 0.77427 1" mesh="thigh_mirror"/>
            <geom size="0.1065 0.01225 0.017" pos="0 0 -0.1065" quat="0.707107 0 0.707107 0" type="box" rgba="0.671705 0.692426 0.77427 1"/>
            <body name="diy_base_link" pos="0 0.002 -0.212" quat="0.707105 0 -0.707108 0">
              <inertial pos="-0.102102 -1.23372e-05 0.0495365" quat="0.465159 0.532549 0.531746 0.466118" mass="0.228917" diaginertia="0.000613223 0.000612296 6.36283e-05"/>
              <joint name="FR_calf_joint" pos="0 0 0" axis="0 1 0" range="-2.9 -1.2" actuatorfrcrange="-45.43 45.43"/>
              <geom type="mesh" contype="0" conaffinity="0" group="1" density="0" rgba="0.627451 0.627451 0.627451 1" mesh="base_link"/>
              <geom type="mesh" rgba="0.627451 0.627451 0.627451 1" mesh="base_link"/>
              <body name="diy_link1" pos="-0.022741 -5e-05 0.032" quat="-3.67321e-06 1 0 0">
                <inertial pos="-0.128815 6.16693e-05 0.0174845" quat="0.60809 0.393539 0.405553 0.557567" mass="0.0589547" diaginertia="1.49592e-05 1.38269e-05 1.14707e-05"/>
                <joint name="diy_joint1" pos="0 0 0" axis="1 0 0" type="slide" range="0 0.1" actuatorfrcrange="-40 40"/>
                <geom type="mesh" contype="0" conaffinity="0" group="1" density="0" rgba="0.627451 0.627451 0.627451 1" mesh="link1"/>
                <geom type="mesh" rgba="0.627451 0.627451 0.627451 1" mesh="link1"/>
                <body name="diy_link2" pos="-0.145983 -0.0292 0.0227">
                  <inertial pos="-0.0412401 0.029 -0.00237298" quat="0.492327 0.492327 -0.507557 0.507557" mass="0.0492722" diaginertia="2.51508e-05 1.61636e-05 1.49982e-05"/>
                  <joint name="diy_joint2" pos="0 0 0" axis="0 -1 0" range="-2.4 0.67" actuatorfrcrange="-4.9 4.9"/>
                  <geom type="mesh" contype="0" conaffinity="0" group="1" density="0" rgba="0.627451 0.627451 0.627451 1" mesh="link2"/>
                  <geom type="mesh" rgba="0.627451 0.627451 0.627451 1" mesh="link2"/>
                  <body name="diy_link3" pos="-0.050675 0.029 0.017145">
                    <inertial pos="-0.0875706 0.00129801 0.0260546" quat="0.38206 0.600628 0.593439 0.375642" mass="0.111403" diaginertia="0.000168687 0.000164287 1.93189e-05"/>
                    <joint name="diy_joint3" pos="0 0 0" axis="0.46021 0 0.88781" range="-1.42 1.45" actuatorfrcrange="-1.39 1.39"/>
                    <geom type="mesh" contype="0" conaffinity="0" group="1" density="0" rgba="0.627451 0.627451 0.627451 1" mesh="link3"/>
                    <geom type="mesh" rgba="0.627451 0.627451 0.627451 1" mesh="link3"/>
                    <body name="diy_link4" pos="-0.12194 -0.015927 0.044362">
                      <inertial pos="-0.0320231 0.0188395 0.019613" quat="0.420708 0.574598 0.569492 0.410513" mass="0.0268788" diaginertia="1.15938e-05 1.13104e-05 1.68093e-06"/>
                      <joint name="diy_joint4" pos="0 0 0" axis="0.014315 0.99987 -0.0074203" range="-0.17 1.4" actuatorfrcrange="-1.39 1.39"/>
                      <geom type="mesh" contype="0" conaffinity="0" group="1" density="0" rgba="0.627451 0.627451 0.627451 1" mesh="link4"/>
                      <geom type="mesh" rgba="0.627451 0.627451 0.627451 1" mesh="link4"/>
                    </body>
                  </body>
                </body>
              </body>
            </body>
          </body>
        </body>
        <body name="RL_hip" pos="-0.1934 0.0465 0">
          <inertial pos="0.00479081 0.00171489 -9.28162e-05" quat="0.504477 0.497915 0.497592 0.499987" mass="0.767" diaginertia="0.000998028 0.000658115 0.000539924"/>
          <joint name="RL_hip_joint" pos="0 0 0" axis="1 0 0" range="-1.0472 1.0472" actuatorfrcrange="-23.7 23.7"/>
          <geom quat="4.63268e-05 0 1 0" type="mesh" contype="0" conaffinity="0" group="1" density="0" rgba="0.671705 0.692426 0.77427 1" mesh="hip"/>
          <geom size="0.046 0.02" pos="0 0.08 0" quat="0.707107 0.707107 0 0" type="cylinder" rgba="0.671705 0.692426 0.77427 1"/>
          <body name="RL_thigh" pos="0 0.0955 0">
            <inertial pos="-0.00115176 -0.0207007 -0.0303549" quat="0.622906 0.0767399 -0.0333173 0.777811" mass="1.241" diaginertia="0.00622804 0.00605116 0.00109601"/>
            <joint name="RL_thigh_joint" pos="0 0 0" axis="0 1 0" range="-0.5236 4.5379" actuatorfrcrange="-23.7 23.7"/>
            <geom type="mesh" contype="0" conaffinity="0" group="1" density="0" rgba="0.671705 0.692426 0.77427 1" mesh="thigh"/>
            <geom size="0.1065 0.01225 0.017" pos="0 0 -0.1065" quat="0.707107 0 0.707107 0" type="box" rgba="0.671705 0.692426 0.77427 1"/>
            <body name="RL_calf" pos="0 0 -0.213">
              <inertial pos="0.00444864 -0.000766071 -0.135538" quat="0.715344 0.00281961 -0.0030272 0.69876" mass="0.196" diaginertia="0.00142074 0.00139944 4.56472e-05"/>
              <joint name="RL_calf_joint" pos="0 0 0" axis="0 1 0" range="-2.7227 -0.83776" actuatorfrcrange="-45.43 45.43"/>
              <geom type="mesh" contype="0" conaffinity="0" group="1" density="0" rgba="0 0 0 1" mesh="calf"/>
              <geom size="0.013 0.06" pos="0.01 0 -0.06" quat="0.995004 0 -0.0998334 0" type="cylinder" rgba="0 0 0 1"/>
              <geom size="0.011 0.0325" pos="0.02 0 -0.148" quat="0.999688 0 0.0249974 0" type="cylinder"/>
              <geom size="0.0155 0.015" pos="0.00801333 0 -0.18745" quat="0.965093 0 0.261909 0" type="cylinder"/>
              <geom pos="0 0 -0.213" quat="1 0 0 0" type="mesh" contype="0" conaffinity="0" group="1" density="0" rgba="0 0 0 1" mesh="foot"/>
              <geom size="0.022" pos="-0.002 0 -0.213" rgba="0 0 0 1"/>
            </body>
          </body>
        </body>
        <body name="RR_hip" pos="-0.1934 -0.0465 0">
          <inertial pos="0.004756 -0.00171489 -9.28162e-05" quat="0.500003 0.497627 0.497899 0.504441" mass="0.767" diaginertia="0.000998282 0.00065837 0.000539924"/>
          <joint name="RR_hip_joint" pos="0 0 0" axis="1 0 0" range="-1.0472 1.0472" actuatorfrcrange="-23.7 23.7"/>
          <geom quat="2.14617e-09 4.63268e-05 4.63268e-05 -1" type="mesh" contype="0" conaffinity="0" group="1" density="0" rgba="0.671705 0.692426 0.77427 1" mesh="hip"/>
          <geom size="0.046 0.02" pos="0 -0.08 0" quat="0.707107 0.707107 0 0" type="cylinder" rgba="0.671705 0.692426 0.77427 1"/>
          <body name="RR_thigh" pos="0 -0.0955 0">
            <inertial pos="-0.0057918 0.0207007 -0.0303549" quat="0.512281 -0.0184867 0.0761773 0.855233" mass="1.241" diaginertia="0.0062377 0.00598212 0.00107542"/>
            <joint name="RR_thigh_joint" pos="0 0 0" axis="0 1 0" range="-0.5236 4.5379" actuatorfrcrange="-23.7 23.7"/>
            <geom type="mesh" contype="0" conaffinity="0" group="1" density="0" rgba="0.671705 0.692426 0.77427 1" mesh="thigh_mirror"/>
            <geom size="0.1065 0.01225 0.017" pos="0 0 -0.1065" quat="0.707107 0 0.707107 0" type="box" rgba="0.671705 0.692426 0.77427 1"/>
            <body name="RR_calf" pos="0 0 -0.213">
              <inertial pos="0.00444864 0.000766071 -0.135538" quat="0.69876 -0.0030272 0.00281961 0.715344" mass="0.196" diaginertia="0.00142074 0.00139944 4.56472e-05"/>
              <joint name="RR_calf_joint" pos="0 0 0" axis="0 1 0" range="-2.7227 -0.83776" actuatorfrcrange="-45.43 45.43"/>
              <geom type="mesh" contype="0" conaffinity="0" group="1" density="0" rgba="0 0 0 1" mesh="calf_mirror"/>
              <geom size="0.013 0.06" pos="0.01 0 -0.06" quat="0.995004 0 -0.0998334 0" type="cylinder" rgba="0 0 0 1"/>
              <geom size="0.011 0.0325" pos="0.02 0 -0.148" quat="0.999688 0 0.0249974 0" type="cylinder"/>
              <geom size="0.0155 0.015" pos="0.00801333 0 -0.18745" quat="0.965093 0 0.261909 0" type="cylinder"/>
              <geom pos="0 0 -0.213" quat="1 0 0 0" type="mesh" contype="0" conaffinity="0" group="1" density="0" rgba="0 0 0 1" mesh="foot"/>
              <geom size="0.022" pos="-0.002 0 -0.213" rgba="0 0 0 1"/>
            </body>
          </body>
        </body>
    </body>
  </worldbody>

  <actuator>
    <position name="FL_hip_joint_actuator" joint="FL_hip_joint" kp="25.0" kv="0.5" ctrlrange="-100 100"/>
    <position name="FL_thigh_joint_actuator" joint="FL_thigh_joint" kp="25.0" kv="0.5" ctrlrange="-100 100"/>
    <position name="FL_calf_joint_actuator" joint="FL_calf_joint" kp="25.0" kv="0.5" ctrlrange="-100 100"/>
    <position name="FL_diy_joint1_actuator" joint="FL_diy_joint1" kp="5000.0" kv="20.0" ctrlrange="0 0.1"/>
    <position name="FL_diy_joint2_actuator" joint="FL_diy_joint2" kp="10.0" kv="0.5" ctrlrange="-2.4 0.67"/>
    <position name="FL_diy_joint3_actuator" joint="FL_diy_joint3" kp="10.0" kv="0.5" ctrlrange="-1.42 1.45"/>
    <position name="FL_diy_joint4_actuator" joint="FL_diy_joint4" kp="10.0" kv="0.5" ctrlrange="-0.17 1.4"/>
    <position name="FR_hip_joint_actuator" joint="FR_hip_joint" kp="25.0" kv="0.5" ctrlrange="-100 100"/>
    <position name="FR_thigh_joint_actuator" joint="FR_thigh_joint" kp="25.0" kv="0.5" ctrlrange="-100 100"/>
    <position name="FR_calf_joint_actuator" joint="FR_calf_joint" kp="25.0" kv="0.5" ctrlrange="-100 100"/>
    <position name="diy_joint1_actuator" joint="diy_joint1" kp="5000.0" kv="20.0" ctrlrange="0 0.1"/>
    <position name="diy_joint2_actuator" joint="diy_joint2" kp="10.0" kv="0.5" ctrlrange="-2.4 0.67"/>
    <position name="diy_joint3_actuator" joint="diy_joint3" kp="10.0" kv="0.5" ctrlrange="-1.42 1.45"/>
    <position name="diy_joint4_actuator" joint="diy_joint4" kp="10.0" kv="0.5" ctrlrange="-0.17 1.4"/>
    <position name="RL_hip_joint_actuator" joint="RL_hip_joint" kp="25.0" kv="0.5" ctrlrange="-100 100"/>
    <position name="RL_thigh_joint_actuator" joint="RL_thigh_joint" kp="25.0" kv="0.5" ctrlrange="-100 100"/>
    <position name="RL_calf_joint_actuator" joint="RL_calf_joint" kp="25.0" kv="0.5" ctrlrange="-100 100"/>
    <position name="RR_hip_joint_actuator" joint="RR_hip_joint" kp="25.0" kv="0.5" ctrlrange="-100 100"/>
    <position name="RR_thigh_joint_actuator" joint="RR_thigh_joint" kp="25.0" kv="0.5" ctrlrange="-100 100"/>
    <position name="RR_calf_joint_actuator" joint="RR_calf_joint" kp="25.0" kv="0.5" ctrlrange="-100 100"/>
  </actuator>

  <sensor>
    <gyro name="gyro" site="imu"/>
    <accelerometer name="accelerometer" site="imu"/>
    <framequat name="imu_quat" objtype="site" objname="imu"/>
  </sensor>

  <keyframe>
    <key name="home" qpos="0 0 0.35 1 0 0 0 0 0.543 -2.07 0.1 0 0 0 0 0.543 -2.07 0.1 0 0 0 0 0.905 -1.78 0 0.905 -1.78"/>
  </keyframe>
</mujoco>
